<?xml version="1.0"?>
<robot name="robot1">
    <material name="grey">
        <color rgba="0.5 0.5 0.5 1"/>    
    </material>

    <material name="white">
        <color rgba="1 1 1 1"/>    
    </material>

    <material name="green">
        <color rgba="0 0.5 0 1"/>    
    </material>

    <link name = "base_footprint" />

    <link name="base_link">
        <visual>
            <geometry>
                <box size="0.6 0.4 0.2"/>
            </geometry>
            <origin xyz="0 0 0.1" rpy="0 0 0"/>
            <material name="green"/>
        </visual>
        <collision>
            <geometry>
                <box size = "0.6 0.4 0.2"/>
            </geometry>
            <origin xyz="0 0 0.1" rpy="0 0 0"/>
        </collision>
        <inertial>
            <mass value="2.0"/>
            <origin xyz="0 0 0.1" rpy="0 0 0"/>
            <inertia ixx="0.01" iyy="0.01" izz="0.01" ixy="0.0" ixz="0.0" iyz="0.0"/>
        </inertial>
    </link>

    <link name = "lidar">
        <visual>
            <geometry>
                <cylinder radius="0.1" length="0.05"/>
            </geometry>
            <origin xyz="0 0 0" rpy="0 0 0"/>
            <material name="white"/>
        </visual>
        <collision>
            <geometry>
                <cylinder radius="0.1" length="0.05"/>
            </geometry>
            <origin xyz="0 0 0" rpy="1.57 0 0"/>
        </collision>
        <inertial>
            <mass value="2.0"/>
            <origin xyz="0 0 0.1" rpy="0 0 0"/>
            <inertia ixx="0.01" iyy="0.01" izz="0.01" ixy="0.0" ixz="0.0" iyz="0.0"/>
        </inertial>
    </link>

    <link name = "left_wheel">
        <visual>
            <geometry>
                <cylinder radius="0.1" length="0.05"/>
            </geometry>
            <origin xyz="0 0 0" rpy="1.57 0 0"/>
            <material name="grey"/>
        </visual>
        <collision>
            <geometry>
                <cylinder radius="0.1" length="0.05"/>
            </geometry>
            <origin xyz="0 0 0" rpy="1.57 0 0"/>
        </collision>
        <gazebo reference="left_wheel">
            <mu1>1.0</mu1>
            <mu2>1.0</mu2>
        </gazebo>
        <inertial>
            <mass value="2.0"/>
            <origin xyz="0 0 0.1" rpy="0 0 0"/>
            <inertia ixx="0.01" iyy="0.01" izz="0.01" ixy="0.0" ixz="0.0" iyz="0.0"/>
        </inertial>
    </link>

    <link name = "right_wheel">
        <visual>
            <geometry>
                <cylinder radius="0.1" length="0.05"/>
            </geometry>
            <origin xyz="0 0 0" rpy="1.57 0 0"/>
            <material name="grey"/>
        </visual>
        <collision>
            <geometry>
                <cylinder radius="0.1" length="0.05"/>
            </geometry>
            <origin xyz="0 0 0" rpy="1.57 0 0"/>
        </collision>
        <gazebo reference="right_wheel">
            <mu1>1.0</mu1>
            <mu2>1.0</mu2>
        </gazebo>
        <inertial>
            <mass value="2.0"/>
            <origin xyz="0 0 0.1" rpy="0 0 0"/>
            <inertia ixx="0.01" iyy="0.01" izz="0.01" ixy="0.0" ixz="0.0" iyz="0.0"/>
        </inertial>
    </link>

    <link name ="caster_wheel">
        <visual>
            <geometry>
                <sphere radius="0.05"/>
            </geometry>
            <origin xyz="0 0 0" rpy="0 0 0"/>
            <material name="grey"/>
        </visual>
        <collision>
            <geometry>
                <sphere radius="0.05"/>
            </geometry>
            <origin xyz="0 0 0" rpy="0 0 0"/>
        </collision>
        <inertial>
            <mass value="2.0"/>
            <origin xyz="0 0 0.1" rpy="0 0 0"/>
            <inertia ixx="0.01" iyy="0.01" izz="0.01" ixy="0.0" ixz="0.0" iyz="0.0"/>
        </inertial>
    </link>

    <joint name="base_joint" type="fixed">
        <parent link="base_footprint"/>
        <child link="base_link"/>
        <origin xyz="0 0 0.1" rpy="0 0 0"/>
    </joint>

    <joint name="base_lidar_joint" type="fixed">
        <parent link="base_link"/>
        <child link="lidar"/>
        <origin xyz="0 0 0.225" rpy="0 0 0"/>
    </joint>    

    <joint name="left_wheel_joint" type="continuous">
        <parent link="base_link"/>
        <child link="left_wheel"/>
        <origin xyz="-0.15 0.225 0" rpy="0 0 0"/>
        <axis xyz="0 1 0"/>
    </joint>

    <joint name="right_wheel_joint" type="continuous">
        <parent link="base_link"/>
        <child link="right_wheel"/>
        <origin xyz="-0.15 -0.225 0" rpy="0 0 0"/>
        <axis xyz="0 1 0"/>
    </joint>

    <joint name="base_caster_wheel_joint" type="fixed">
        <parent link="base_link"/>
        <child link="caster_wheel"/>
        <origin xyz="0.2 0 -0.05" rpy="0 0 0"/>
        <axis xyz="0 1 0"/>
    </joint>

    <transmission name="left_wheel_trans">
        <type>transmission_interface/SimpleTransmission</type>
        <joint name="left_wheel_joint">
            <hardwareInterface>hardware_interface/VelocityJointInterface</hardwareInterface>
        </joint>
        <actuator name="left_motor">
            <hardwareInterface>hardware_interface/VelocityJointInterface</hardwareInterface>
            <mechanicalReduction>1</mechanicalReduction>
        </actuator>
    </transmission>

    <transmission name="right_wheel_trans">
        <type>transmission_interface/SimpleTransmission</type>
        <joint name="right_wheel_joint">
            <hardwareInterface>hardware_interface/VelocityJointInterface</hardwareInterface>
        </joint>
        <actuator name="right_motor">
            <hardwareInterface>hardware_interface/VelocityJointInterface</hardwareInterface>
            <mechanicalReduction>1</mechanicalReduction>
        </actuator>
    </transmission>


    <gazebo>
        <plugin name="gazebo_ros_control" filename="libgazebo_ros2_control.so"/>
    </gazebo>

    <gazebo>
        <plugin name="diff_drive_controller" filename="libgazebo_ros_diff_drive.so">
            <ros>
                <remapping>cmd_vel:=/cmd_vel</remapping>
                <remapping>odom:=/odom</remapping>
            </ros>
            <updateRate>50</updateRate>
            <leftJoint>left_wheel_joint</leftJoint>
            <rightJoint>right_wheel_joint</rightJoint>
            <wheelSeparation>0.45</wheelSeparation>
            <wheelDiameter>0.2</wheelDiameter>
            <torque>5</torque>
            <commandTopic>/cmd_vel</commandTopic>
            <odometryTopic>/odom</odometryTopic>
            <odometryFrame>odom</odometryFrame>
            <robotBaseFrame>base_link</robotBaseFrame>
            <publishWheelTF>false</publishWheelTF>
        </plugin>
    </gazebo>


</robot>
